# 异常

## 结构

```python
try:
    "执行代码"
except:
    "发生异常时执行的代码"
else:
    "没有异常时执行的代码"
finally:
    "不管有没有异常都会执行的代码"
```



## try & except 块

写代码的时候，出现错误必不可免，即使代码没有问题，也可能遇到别的问题。

看下面这段代码：

```python 
import math

while True:
    text = raw_input('> ')
    if text[0] == 'q':
        break
    x = float(text)
    y = math.log10(x)
    print "log10({0}) = {1}".format(x, y)
```

这段代码接收命令行的输入，当输入为数字时，计算它的对数并输出，直到输入值为 `q` 为止。

乍看没什么问题，然而当我们输入0或者负数时：


```python
import math

while True:
    text = raw_input('> ')
    if text[0] == 'q':
        break
    x = float(text)
    y = math.log10(x)
    print "log10({0}) = {1}".format(x, y)
```
```
    > -1
    ---------------------------------------------------------------------------
    
    ValueError                                Traceback (most recent call last)
    
    <ipython-input-1-ceb8cf66641b> in <module>()
          6         break
          7     x = float(text)
    ----> 8     y = math.log10(x)
          9     print "log10({0}) = {1}".format(x, y)


    ValueError: math domain error
```

`log10` 函数会报错，因为不能接受非正值。

一旦报错，程序就会停止执行，如果不希望程序停止执行，那么我们可以添加一对 `try & except`： 

```python
import math

while True:
    try:
        text = raw_input('> ')
        if text[0] == 'q':
            break
        x = float(text)
        y = math.log10(x)
        print "log10({0}) = {1}".format(x, y)
    except ValueError:
        print "the value must be greater than 0"
```

一旦 `try` 块中的内容出现了异常，那么 `try` 块后面的内容会被忽略，**Python**会寻找 `except` 里面有没有对应的内容，如果找到，就执行对应的块，没有则抛出这个异常。

在上面的例子中，`try` 抛出的是 `ValueError`，`except` 中有对应的内容，所以这个异常被 `except` 捕捉到，程序可以继续执行：


```python
import math

while True:
    try:
        text = raw_input('> ')
        if text[0] == 'q':
            break
        x = float(text)
        y = math.log10(x)
        print "log10({0}) = {1}".format(x, y)
    except ValueError:
        print "the value must be greater than 0"
```
```
    > -1
    the value must be greater than 0
    > 0
    the value must be greater than 0
    > 1
    log10(1.0) = 0.0
    > q
```



## 捕捉不同的错误类型

``` python
import math

while True:
    try:
        text = raw_input('> ')
        if text[0] == 'q':
            break
        x = float(text)
        y = 1 / math.log10(x)
        print "log10({0}) = {1}".format(x, y)
    except ValueError:
        print "the value must be greater than 0"
```

假设我们将这里的 `y` 更改为 `1 / math.log10(x)`，此时输入 `1`：


```python
import math

while True:
    try:
        text = raw_input('> ')
        if text[0] == 'q':
            break
        x = float(text)
        y = 1 / math.log10(x)
        print "log10({0}) = {1}".format(x, y)
    except ValueError:
        print "the value must be greater than 0"
```
```
    > 1
    ---------------------------------------------------------------------------
    
    ZeroDivisionError                         Traceback (most recent call last)
    
    <ipython-input-3-7607f1ae6af9> in <module>()
          7             break
          8         x = float(text)
    ----> 9         y = 1 / math.log10(x)
         10         print "log10({0}) = {1}".format(x, y)
         11     except ValueError:


    ZeroDivisionError: float division by zero
```

因为我们的 `except` 里面并没有 `ZeroDivisionError`，所以会抛出这个异常，我们可以通过两种方式解决这个问题：



## 捕捉所有异常

将`except` 的值改成 `Exception` 类，来捕获所有的异常。


```python
import math

while True:
    try:
        text = raw_input('> ')
        if text[0] == 'q':
            break
        x = float(text)
        y = 1 / math.log10(x)
        print "1 / log10({0}) = {1}".format(x, y)
    except Exception:
        print "invalid value"
```
```
    > 1
    invalid value
    > 0
    invalid value
    > -1
    invalid value
    > 2
    1 / log10(2.0) = 3.32192809489
    > q
```



## 指定特定值

这里，我们把 `ZeroDivisionError` 加入 `except` 。


```python
import math

while True:
    try:
        text = raw_input('> ')
        if text[0] == 'q':
            break
        x = float(text)
        y = 1 / math.log10(x)
        print "1 / log10({0}) = {1}".format(x, y)
    except (ValueError, ZeroDivisionError):
        print "invalid value"
```
```
    > 1
    invalid value
    > -1
    invalid value
    > 0
    invalid value
    > q
```

或者另加处理：


```python
import math

while True:
    try:
        text = raw_input('> ')
        if text[0] == 'q':
            break
        x = float(text)
        y = 1 / math.log10(x)
        print "1 / log10({0}) = {1}".format(x, y)
    except ValueError:
        print "the value must be greater than 0"
    except ZeroDivisionError:
        print "the value must not be 1"
```
```
    > 1
    the value must not be 1
    > -1
    the value must be greater than 0
    > 0
    the value must be greater than 0
    > 2
    1 / log10(2.0) = 3.32192809489
    > q
```

事实上,我们还可以将这两种方式结合起来,用 `Exception` 来捕捉其他的错误：


```python
import math

while True:
    try:
        text = input('> ')
        if text[0] == 'q':
            break
        x = float(text)
        y = 1 / math.log10(x)
        print("1 / log10({0}) = {1}".format(x, y))
    except ValueError:
        print("the value must be greater than 0")
    except ZeroDivisionError:
        print("the value must not be 1")
    except Exception:
        print("unexpected error")
```
```
    > 1
    the value must not be 1
    > -1
    the value must be greater than 0
    > 0
    the value must be greater than 0
    > q
```



## 得到异常的具体信息

在上面的例子中，当我们输入不能转换为浮点数的字符串时，它输出的是 `the value must be greater than 0`，这并没有反映出实际情况。


```python
float('a')
```

```
    ---------------------------------------------------------------------------
    
    ValueError                                Traceback (most recent call last)
    
    <ipython-input-8-99859da4e72c> in <module>()
    ----> 1 float('a')


    ValueError: could not convert string to float: a
```

为了得到异常的具体信息，我们将这个 `ValueError` 具现化：


```python
import math

while True:
    try:
        text = raw_input('> ')
        if text[0] == 'q':
            break
        x = float(text)
        y = 1 / math.log10(x)
        print "1 / log10({0}) = {1}".format(x, y)
    except ValueError as exc:
        if exc.message == "math domain error":
            print "the value must be greater than 0"
        else:
            print "could not convert '%s' to float" % text
    except ZeroDivisionError:
        print "the value must not be 1"
    except Exception as exc:
        print "unexpected error:", exc.message
```
```
    > 1
    the value must not be 1
    > -1
    the value must be greater than 0
    > aa
    could not convert 'aa' to float
    > q
```

同时，我们也将捕获的其他异常的信息显示出来。

这里，`exc.message` 显示的内容是异常对应的说明，例如

    ValueError: could not convert string to float: a

对应的 `message` 是 

    could not convert string to float: a

当我们使用 `except Exception` 时，会捕获所有的 `Exception` 和它派生出来的子类，但不是所有的异常都是从 `Exception` 类派生出来的，可能会出现一些不能捕获的情况，因此，更加一般的做法是使用这样的形式：

```python
try:
    pass
except:
    pass
```

这样不指定异常的类型会捕获所有的异常，但是这样的形式并不推荐。



## 自定义异常

异常是标准库中的类，这意味着我们可以自定义异常类：


```python
class CommandError(ValueError):
    pass
```

这里我们定义了一个继承自 `ValueError` 的异常类，异常类一般接收一个字符串作为输入，并把这个字符串当作异常信息，例如：


```python
valid_commands = {'start', 'stop', 'pause'}

while True:
    command = raw_input('> ')
    if command.lower() not in valid_commands:
        raise CommandError('Invalid commmand: %s' % command)
```
```
    > bad command
    ---------------------------------------------------------------------------
    
    CommandError                              Traceback (most recent call last)
    
    <ipython-input-11-0e1f81a1136d> in <module>()
          4     command = raw_input('> ')
          5     if command.lower() not in valid_commands:
    ----> 6         raise CommandError('Invalid commmand: %s' % command)


    CommandError: Invalid commmand: bad command
```

我们使用 `raise` 关键词来抛出异常。

我们可以使用 `try/except` 块来捕捉这个异常：

``` python
valid_commands = {'start', 'stop', 'pause'}

while True:
    command = raw_input('> ')
    try:
        if command.lower() not in valid_commands:
            raise CommandError('Invalid commmand: %s' % command)
    except CommandError:
        print 'Bad command string: "%s"' % command
```

由于 `CommandError` 继承自 `ValueError`，我们也可以使用 `except ValueError` 来捕获这个异常。



## raise 抛出异常

在 Python 中，`raise` 是用于触发异常的关键字。它允许程序员显式地引发（raise）一个特定类型的异常，并指定需要抛出的异常对象。

通过使用 `raise` 关键字，可以在代码中主动引发异常，从而改变程序的正常执行流程。当某些特定条件不满足、错误发生或其他需要中断程序时，可以使用 `raise` 关键字来引发适当的异常。

`raise` 的基本语法如下：

```python
raise [Exception [详细信息]]
```

其中，`Exception` 是要引发的异常类别或实例。**它可以是内置的异常类，也可以是自定义的异常类**。`详细信息` 是可选的，用于提供有关异常的附加信息。

以下是一些示例：

1. 引发内置异常类的实例：

```python
raise ValueError("无效的值")
```

2. 引发自定义异常类的实例：

```python
class CustomError(Exception):
    pass

raise CustomError("自定义错误")
```

3. 直接引发异常类对象：

```python
raise ValueError
```

当 `raise` 语句执行时，**程序将立即跳转到最近的异常处理机制。如果没有合适的异常处理机制，程序将终止并打印异常信息**。

`raise` 语句通常与条件结合使用，以便根据程序状态、输入或其他因素决定是否引发异常。它使程序员能够更好地控制异常的引发时机，从而实现错误处理和逻辑流程的调整。

请注意，**`raise` 引发的异常可以在调用者层级中进行捕获和处理。如果没有合适的异常处理，异常将向上游传播，直到被解释器捕获或导致程序终止**。

```python
x = 10
if x > 5:
    raise Exception('x 不能大于 5。x 的值为: {}'.format(x))
```

```
Traceback (most recent call last):
  File "test.py", line 3, in <module>
    raise Exception('x 不能大于 5。x 的值为: {}'.format(x))
Exception: x 不能大于 5。x 的值为: 10
```





## finally

try/catch 块还有一个可选的关键词 finally。

不管 try 块有没有异常， finally 块的内容总是会被执行，而且会在抛出异常前执行，因此可以用来作为安全保证，比如确保打开的文件被关闭。

finally 块执行的时机：

- 首先不管有没有异常都会执行
- 如果异常没有被捕获，会先执行 finally 块，再输出异常
- 如果异常被 except 捕获了，会在 except 块后执行

看看例子：


```python
try:
    print 1
finally:
    print 'finally was called.'
```

    1
    finally was called.


在抛出异常前执行：


```python
try:
    print 1 / 0
finally:
    print 'finally was called.'
```
```
    finally was called.
    ---------------------------------------------------------------------------
    
    ZeroDivisionError                         Traceback (most recent call last)
    
    <ipython-input-13-87ecdf8b9265> in <module>()
          1 try:
    ----> 2     print 1 / 0
          3 finally:
          4     print 'finally was called.'


    ZeroDivisionError: integer division or modulo by zero
```

如果异常被捕获了，在最后执行：


```python
try:
    print 1 / 0
except ZeroDivisionError:
    print 'divide by 0.'
finally:
    print 'finally was called.'
```

    divide by 0.
    finally was called.

在 Python 的异常处理中，`finally` 块会在无论是否发生异常都会执行的情况下执行。**它通常用于执行一些无论异常是否发生都需要进行清理或收尾操作的代码**。

无论是 `try` 块中发生了异常，还是没有发生异常，`finally` 块中的代码都会被执行。这样可以确保在任何情况下都能够释放资源、关闭文件或执行其他必要的操作。

下面是一个简单的示例：

```python
def divide(x, y):
    try:
        result = x / y
        print("计算结果:", result)
    except ZeroDivisionError:
        print("除数不能为零！")
    finally:
        print("执行 finally 块")

# 示例调用
divide(4, 2)
divide(4, 0)
```

输出：
```
计算结果: 2.0
执行 finally 块
除数不能为零！
执行 finally 块
```

在上述示例中，`divide` 函数尝试进行两个数相除的计算。第一个调用传递的参数是有效的，计算成功，并打印结果。而第二个调用尝试将除数设为零，触发了 ZeroDivisionError 异常，但无论如何，`finally` 块中的代码始终被执行。

请注意，**即使在 `try` 块或 `except` 块中使用了 `return` 语句，`finally` 块仍会在函数返回之前执行**。



## assert 断言

在 Python 中，`assert` 是一种用于断言（assertion）的语句。**它用于检查条件是否为真。如果断言条件为假（False），则会引发 `AssertionError` 异常**。

`assert` 语句通常用于在代码中检查某些预期条件是否满足，如果不满足，则表示程序的状态出现了错误或逻辑上的错误。

`assert` 语句的语法如下:

```python
assert 条件, 错误信息
```

其中，`条件` 是一个布尔表达式，如果为 False，则触发断言失败；`错误信息` 是可选的，可以是一个字符串，用于说明断言失败的原因。

以下是一个示例：

```python
def divide(x, y):
    assert y != 0, "除数不能为零！"
    result = x / y
    return result

# 示例调用
print(divide(4, 2))
print(divide(4, 0))
```

输出：
```
2.0
Traceback (most recent call last):
  File "<stdin>", line 1, in <module>
  File "<stdin>", line 2, in divide
AssertionError: 除数不能为零！
```

在上述示例中，`divide` 函数使用 `assert` 语句来确保除数不为零。第一个调用传递了有效的参数，而第二个调用尝试将除数设置为零，违反了预期条件，并触发了 `AssertionError` 异常。

`assert` 语句主要用于调试和测试阶段，帮助程序员捕捉潜在的问题或错误。在正常情况下，断言应该为真，因此如果出现断言失败，则意味着程序中出现了问题。

断言可以在条件不满足程序运行的情况下直接返回错误，而不必等待程序运行后出现崩溃的情况，例如我们的代码只能在 Linux 系统下运行，可以先判断当前系统是否符合条件。以下实例判断当前系统是否为 Linux，**如果不满足条件则直接触发异常，不必执行接下来的代码**：

```python
import sys
assert ('linux' in sys.platform), "该代码只能在 Linux 下执行"

# 接下来要执行的代码
```



## with 打开文件

Python 中的 with 语句用于异常处理，封装了 try…except…finally 编码范式，提高了易用性。with 语句使代码更清晰、更具可读性， **它简化了文件流等公共资源的管理**。**在处理文件对象时使用 with 关键字是一种很好的做法**。

我们可以看下以下几种代码实例：

不使用 with，也不使用 try…except…finally

```python
file = open('./test_runoob.txt', 'w')
file.write('hello world !')
file.close()
```

**以上代码如果在调用 write 的过程中，出现了异常，则 close 方法将无法被执行，因此资源就会一直被该程序占用而无法被释放**。 接下来我们使用 try…except…finally 来改进代码：

```python
file = open('./test_runoob.txt', 'w')
try:
    file.write('hello world')
finally:  # 不管出不出异常，finally块都会执行
    file.close()
```

以上代码我们对可能发生异常的代码处进行 try 捕获，发生异常时执行 except 代码块，finally 代码块是无论什么情况都会执行，所以文件会被关闭，不会因为执行异常而占用资源。

使用 **with** 关键字：

```python
with open('./test_runoob.txt', 'w') as file:
    file.write('hello world !')
```

使用 **with** 关键字系统会自动调用 f.close() 方法， with 的作用等效于 try/finally 语句是一样的。

我们可以在执行 with 关键字后检验文件是否关闭：

```python
>>> with open('./test_runoob.txt') as f:
        read_data = f.read()

>>> # 查看文件是否关闭
>>> f.closed
True
```

在文件对象中定义了 `__enter__` 和 `__exit__` 方法，**即文件对象也实现了上下文管理器，首先调用 `__enter__` 方法，然后执行 with 语句中的代码，最后调用 `__exit__` 方法。** 即使出现错误，也会调用 `__exit__` 方法，也就是会关闭文件流。



> 更多内容看：[with的用法](with的用法.md)



## 更多内容

[Python3 错误和异常 | 菜鸟教程 (runoob.com)](https://www.runoob.com/python3/python3-errors-execptions.html)

[Python3 assert（断言） | 菜鸟教程 (runoob.com)](https://www.runoob.com/python3/python3-assert.html)
